[31m[1mWARNING: This is a development server. Do not use it in a production deployment. Use a production WSGI server instead.[0m
 * Running on all addresses (0.0.0.0)
 * Running on https://127.0.0.1:8080
 * Running on https://192.168.145.9:8080
[33mPress CTRL+C to quit[0m
 * Restarting with stat
 * Debugger is active!
 * Debugger PIN: 545-548-095
Invalid HTTP_HOST header: '150.254.165.23:8080'. You may need to add '150.254.165.23' to ALLOWED_HOSTS.
Traceback (most recent call last):
  File "/data/work/arysto/TinyLink/venv/lib64/python3.9/site-packages/django/core/handlers/exception.py", line 55, in inner
    response = get_response(request)
  File "/data/work/arysto/TinyLink/venv/lib64/python3.9/site-packages/django/utils/deprecation.py", line 133, in __call__
    response = self.process_request(request)
  File "/data/work/arysto/TinyLink/venv/lib64/python3.9/site-packages/django/middleware/common.py", line 48, in process_request
    host = request.get_host()
  File "/data/work/arysto/TinyLink/venv/lib64/python3.9/site-packages/django/http/request.py", line 150, in get_host
    raise DisallowedHost(msg)
django.core.exceptions.DisallowedHost: Invalid HTTP_HOST header: '150.254.165.23:8080'. You may need to add '150.254.165.23' to ALLOWED_HOSTS.
Invalid HTTP_HOST header: '150.254.165.23:8080'. You may need to add '150.254.165.23' to ALLOWED_HOSTS.
Traceback (most recent call last):
  File "/data/work/arysto/TinyLink/venv/lib64/python3.9/site-packages/django/core/handlers/exception.py", line 55, in inner
    response = get_response(request)
  File "/data/work/arysto/TinyLink/venv/lib64/python3.9/site-packages/django/utils/deprecation.py", line 134, in __call__
    response = response or self.get_response(request)
  File "/data/work/arysto/TinyLink/venv/lib64/python3.9/site-packages/django/core/handlers/exception.py", line 57, in inner
    response = response_for_exception(request, exc)
  File "/data/work/arysto/TinyLink/venv/lib64/python3.9/site-packages/django/core/handlers/exception.py", line 130, in response_for_exception
    response = debug.technical_500_response(
  File "/data/work/arysto/TinyLink/venv/lib64/python3.9/site-packages/django_extensions/management/technical_response.py", line 42, in null_technical_500_response
    raise exc_value
  File "/data/work/arysto/TinyLink/venv/lib64/python3.9/site-packages/django/core/handlers/exception.py", line 55, in inner
    response = get_response(request)
  File "/data/work/arysto/TinyLink/venv/lib64/python3.9/site-packages/django/utils/deprecation.py", line 133, in __call__
    response = self.process_request(request)
  File "/data/work/arysto/TinyLink/venv/lib64/python3.9/site-packages/django/middleware/common.py", line 48, in process_request
    host = request.get_host()
  File "/data/work/arysto/TinyLink/venv/lib64/python3.9/site-packages/django/http/request.py", line 150, in get_host
    raise DisallowedHost(msg)
django.core.exceptions.DisallowedHost: Invalid HTTP_HOST header: '150.254.165.23:8080'. You may need to add '150.254.165.23' to ALLOWED_HOSTS.
Invalid HTTP_HOST header: '150.254.165.23:8080'. You may need to add '150.254.165.23' to ALLOWED_HOSTS.
Traceback (most recent call last):
  File "/data/work/arysto/TinyLink/venv/lib64/python3.9/site-packages/django/core/handlers/exception.py", line 55, in inner
    response = get_response(request)
  File "/data/work/arysto/TinyLink/venv/lib64/python3.9/site-packages/django/utils/deprecation.py", line 134, in __call__
    response = response or self.get_response(request)
  File "/data/work/arysto/TinyLink/venv/lib64/python3.9/site-packages/django/core/handlers/exception.py", line 57, in inner
    response = response_for_exception(request, exc)
  File "/data/work/arysto/TinyLink/venv/lib64/python3.9/site-packages/django/core/handlers/exception.py", line 130, in response_for_exception
    response = debug.technical_500_response(
  File "/data/work/arysto/TinyLink/venv/lib64/python3.9/site-packages/django_extensions/management/technical_response.py", line 42, in null_technical_500_response
    raise exc_value
  File "/data/work/arysto/TinyLink/venv/lib64/python3.9/site-packages/django/core/handlers/exception.py", line 55, in inner
    response = get_response(request)
  File "/data/work/arysto/TinyLink/venv/lib64/python3.9/site-packages/django/utils/deprecation.py", line 134, in __call__
    response = response or self.get_response(request)
  File "/data/work/arysto/TinyLink/venv/lib64/python3.9/site-packages/django/core/handlers/exception.py", line 57, in inner
    response = response_for_exception(request, exc)
  File "/data/work/arysto/TinyLink/venv/lib64/python3.9/site-packages/django/core/handlers/exception.py", line 130, in response_for_exception
    response = debug.technical_500_response(
  File "/data/work/arysto/TinyLink/venv/lib64/python3.9/site-packages/django_extensions/management/technical_response.py", line 42, in null_technical_500_response
    raise exc_value
  File "/data/work/arysto/TinyLink/venv/lib64/python3.9/site-packages/django/core/handlers/exception.py", line 55, in inner
    response = get_response(request)
  File "/data/work/arysto/TinyLink/venv/lib64/python3.9/site-packages/django/utils/deprecation.py", line 133, in __call__
    response = self.process_request(request)
  File "/data/work/arysto/TinyLink/venv/lib64/python3.9/site-packages/django/middleware/common.py", line 48, in process_request
    host = request.get_host()
  File "/data/work/arysto/TinyLink/venv/lib64/python3.9/site-packages/django/http/request.py", line 150, in get_host
    raise DisallowedHost(msg)
django.core.exceptions.DisallowedHost: Invalid HTTP_HOST header: '150.254.165.23:8080'. You may need to add '150.254.165.23' to ALLOWED_HOSTS.
Invalid HTTP_HOST header: '150.254.165.23:8080'. You may need to add '150.254.165.23' to ALLOWED_HOSTS.
Traceback (most recent call last):
  File "/data/work/arysto/TinyLink/venv/lib64/python3.9/site-packages/django/core/handlers/exception.py", line 55, in inner
    response = get_response(request)
  File "/data/work/arysto/TinyLink/venv/lib64/python3.9/site-packages/corsheaders/middleware.py", line 56, in __call__
    result = self.get_response(request)
  File "/data/work/arysto/TinyLink/venv/lib64/python3.9/site-packages/django/core/handlers/exception.py", line 57, in inner
    response = response_for_exception(request, exc)
  File "/data/work/arysto/TinyLink/venv/lib64/python3.9/site-packages/django/core/handlers/exception.py", line 130, in response_for_exception
    response = debug.technical_500_response(
  File "/data/work/arysto/TinyLink/venv/lib64/python3.9/site-packages/django_extensions/management/technical_response.py", line 42, in null_technical_500_response
    raise exc_value
  File "/data/work/arysto/TinyLink/venv/lib64/python3.9/site-packages/django/core/handlers/exception.py", line 55, in inner
    response = get_response(request)
  File "/data/work/arysto/TinyLink/venv/lib64/python3.9/site-packages/django/utils/deprecation.py", line 134, in __call__
    response = response or self.get_response(request)
  File "/data/work/arysto/TinyLink/venv/lib64/python3.9/site-packages/django/core/handlers/exception.py", line 57, in inner
    response = response_for_exception(request, exc)
  File "/data/work/arysto/TinyLink/venv/lib64/python3.9/site-packages/django/core/handlers/exception.py", line 130, in response_for_exception
    response = debug.technical_500_response(
  File "/data/work/arysto/TinyLink/venv/lib64/python3.9/site-packages/django_extensions/management/technical_response.py", line 42, in null_technical_500_response
    raise exc_value
  File "/data/work/arysto/TinyLink/venv/lib64/python3.9/site-packages/django/core/handlers/exception.py", line 55, in inner
    response = get_response(request)
  File "/data/work/arysto/TinyLink/venv/lib64/python3.9/site-packages/django/utils/deprecation.py", line 134, in __call__
    response = response or self.get_response(request)
  File "/data/work/arysto/TinyLink/venv/lib64/python3.9/site-packages/django/core/handlers/exception.py", line 57, in inner
    response = response_for_exception(request, exc)
  File "/data/work/arysto/TinyLink/venv/lib64/python3.9/site-packages/django/core/handlers/exception.py", line 130, in response_for_exception
    response = debug.technical_500_response(
  File "/data/work/arysto/TinyLink/venv/lib64/python3.9/site-packages/django_extensions/management/technical_response.py", line 42, in null_technical_500_response
    raise exc_value
  File "/data/work/arysto/TinyLink/venv/lib64/python3.9/site-packages/django/core/handlers/exception.py", line 55, in inner
    response = get_response(request)
  File "/data/work/arysto/TinyLink/venv/lib64/python3.9/site-packages/django/utils/deprecation.py", line 133, in __call__
    response = self.process_request(request)
  File "/data/work/arysto/TinyLink/venv/lib64/python3.9/site-packages/django/middleware/common.py", line 48, in process_request
    host = request.get_host()
  File "/data/work/arysto/TinyLink/venv/lib64/python3.9/site-packages/django/http/request.py", line 150, in get_host
    raise DisallowedHost(msg)
django.core.exceptions.DisallowedHost: Invalid HTTP_HOST header: '150.254.165.23:8080'. You may need to add '150.254.165.23' to ALLOWED_HOSTS.
104.234.115.146 - - [22/May/2025 10:42:25] "[35m[1mGET /web/ HTTP/1.1[0m" 500 -
Traceback (most recent call last):
  File "/data/work/arysto/TinyLink/venv/lib64/python3.9/site-packages/django/contrib/staticfiles/handlers.py", line 80, in __call__
    return self.application(environ, start_response)
  File "/data/work/arysto/TinyLink/venv/lib64/python3.9/site-packages/django/core/handlers/wsgi.py", line 124, in __call__
    response = self.get_response(request)
  File "/data/work/arysto/TinyLink/venv/lib64/python3.9/site-packages/django/core/handlers/base.py", line 140, in get_response
    response = self._middleware_chain(request)
  File "/data/work/arysto/TinyLink/venv/lib64/python3.9/site-packages/django/core/handlers/exception.py", line 57, in inner
    response = response_for_exception(request, exc)
  File "/data/work/arysto/TinyLink/venv/lib64/python3.9/site-packages/django/core/handlers/exception.py", line 130, in response_for_exception
    response = debug.technical_500_response(
  File "/data/work/arysto/TinyLink/venv/lib64/python3.9/site-packages/django_extensions/management/technical_response.py", line 42, in null_technical_500_response
    raise exc_value
  File "/data/work/arysto/TinyLink/venv/lib64/python3.9/site-packages/django/core/handlers/exception.py", line 55, in inner
    response = get_response(request)
  File "/data/work/arysto/TinyLink/venv/lib64/python3.9/site-packages/corsheaders/middleware.py", line 56, in __call__
    result = self.get_response(request)
  File "/data/work/arysto/TinyLink/venv/lib64/python3.9/site-packages/django/core/handlers/exception.py", line 57, in inner
    response = response_for_exception(request, exc)
  File "/data/work/arysto/TinyLink/venv/lib64/python3.9/site-packages/django/core/handlers/exception.py", line 130, in response_for_exception
    response = debug.technical_500_response(
  File "/data/work/arysto/TinyLink/venv/lib64/python3.9/site-packages/django_extensions/management/technical_response.py", line 42, in null_technical_500_response
    raise exc_value
  File "/data/work/arysto/TinyLink/venv/lib64/python3.9/site-packages/django/core/handlers/exception.py", line 55, in inner
    response = get_response(request)
  File "/data/work/arysto/TinyLink/venv/lib64/python3.9/site-packages/django/utils/deprecation.py", line 134, in __call__
    response = response or self.get_response(request)
  File "/data/work/arysto/TinyLink/venv/lib64/python3.9/site-packages/django/core/handlers/exception.py", line 57, in inner
    response = response_for_exception(request, exc)
  File "/data/work/arysto/TinyLink/venv/lib64/python3.9/site-packages/django/core/handlers/exception.py", line 130, in response_for_exception
    response = debug.technical_500_response(
  File "/data/work/arysto/TinyLink/venv/lib64/python3.9/site-packages/django_extensions/management/technical_response.py", line 42, in null_technical_500_response
    raise exc_value
  File "/data/work/arysto/TinyLink/venv/lib64/python3.9/site-packages/django/core/handlers/exception.py", line 55, in inner
    response = get_response(request)
  File "/data/work/arysto/TinyLink/venv/lib64/python3.9/site-packages/django/utils/deprecation.py", line 134, in __call__
    response = response or self.get_response(request)
  File "/data/work/arysto/TinyLink/venv/lib64/python3.9/site-packages/django/core/handlers/exception.py", line 57, in inner
    response = response_for_exception(request, exc)
  File "/data/work/arysto/TinyLink/venv/lib64/python3.9/site-packages/django/core/handlers/exception.py", line 130, in response_for_exception
    response = debug.technical_500_response(
  File "/data/work/arysto/TinyLink/venv/lib64/python3.9/site-packages/django_extensions/management/technical_response.py", line 42, in null_technical_500_response
    raise exc_value
  File "/data/work/arysto/TinyLink/venv/lib64/python3.9/site-packages/django/core/handlers/exception.py", line 55, in inner
    response = get_response(request)
  File "/data/work/arysto/TinyLink/venv/lib64/python3.9/site-packages/django/utils/deprecation.py", line 133, in __call__
    response = self.process_request(request)
  File "/data/work/arysto/TinyLink/venv/lib64/python3.9/site-packages/django/middleware/common.py", line 48, in process_request
    host = request.get_host()
  File "/data/work/arysto/TinyLink/venv/lib64/python3.9/site-packages/django/http/request.py", line 150, in get_host
    raise DisallowedHost(msg)
django.core.exceptions.DisallowedHost: Invalid HTTP_HOST header: '150.254.165.23:8080'. You may need to add '150.254.165.23' to ALLOWED_HOSTS.
Invalid HTTP_HOST header: '150.254.165.23:8080'. You may need to add '150.254.165.23' to ALLOWED_HOSTS.
Traceback (most recent call last):
  File "/data/work/arysto/TinyLink/venv/lib64/python3.9/site-packages/django/core/handlers/exception.py", line 55, in inner
    response = get_response(request)
  File "/data/work/arysto/TinyLink/venv/lib64/python3.9/site-packages/django/utils/deprecation.py", line 133, in __call__
    response = self.process_request(request)
  File "/data/work/arysto/TinyLink/venv/lib64/python3.9/site-packages/django/middleware/common.py", line 48, in process_request
    host = request.get_host()
  File "/data/work/arysto/TinyLink/venv/lib64/python3.9/site-packages/django/http/request.py", line 150, in get_host
    raise DisallowedHost(msg)
django.core.exceptions.DisallowedHost: Invalid HTTP_HOST header: '150.254.165.23:8080'. You may need to add '150.254.165.23' to ALLOWED_HOSTS.
Invalid HTTP_HOST header: '150.254.165.23:8080'. You may need to add '150.254.165.23' to ALLOWED_HOSTS.
Traceback (most recent call last):
  File "/data/work/arysto/TinyLink/venv/lib64/python3.9/site-packages/django/core/handlers/exception.py", line 55, in inner
    response = get_response(request)
  File "/data/work/arysto/TinyLink/venv/lib64/python3.9/site-packages/django/utils/deprecation.py", line 134, in __call__
    response = response or self.get_response(request)
  File "/data/work/arysto/TinyLink/venv/lib64/python3.9/site-packages/django/core/handlers/exception.py", line 57, in inner
    response = response_for_exception(request, exc)
  File "/data/work/arysto/TinyLink/venv/lib64/python3.9/site-packages/django/core/handlers/exception.py", line 130, in response_for_exception
    response = debug.technical_500_response(
  File "/data/work/arysto/TinyLink/venv/lib64/python3.9/site-packages/django_extensions/management/technical_response.py", line 42, in null_technical_500_response
    raise exc_value
  File "/data/work/arysto/TinyLink/venv/lib64/python3.9/site-packages/django/core/handlers/exception.py", line 55, in inner
    response = get_response(request)
  File "/data/work/arysto/TinyLink/venv/lib64/python3.9/site-packages/django/utils/deprecation.py", line 133, in __call__
    response = self.process_request(request)
  File "/data/work/arysto/TinyLink/venv/lib64/python3.9/site-packages/django/middleware/common.py", line 48, in process_request
    host = request.get_host()
  File "/data/work/arysto/TinyLink/venv/lib64/python3.9/site-packages/django/http/request.py", line 150, in get_host
    raise DisallowedHost(msg)
django.core.exceptions.DisallowedHost: Invalid HTTP_HOST header: '150.254.165.23:8080'. You may need to add '150.254.165.23' to ALLOWED_HOSTS.
Invalid HTTP_HOST header: '150.254.165.23:8080'. You may need to add '150.254.165.23' to ALLOWED_HOSTS.
Traceback (most recent call last):
  File "/data/work/arysto/TinyLink/venv/lib64/python3.9/site-packages/django/core/handlers/exception.py", line 55, in inner
    response = get_response(request)
  File "/data/work/arysto/TinyLink/venv/lib64/python3.9/site-packages/django/utils/deprecation.py", line 134, in __call__
    response = response or self.get_response(request)
  File "/data/work/arysto/TinyLink/venv/lib64/python3.9/site-packages/django/core/handlers/exception.py", line 57, in inner
    response = response_for_exception(request, exc)
  File "/data/work/arysto/TinyLink/venv/lib64/python3.9/site-packages/django/core/handlers/exception.py", line 130, in response_for_exception
    response = debug.technical_500_response(
  File "/data/work/arysto/TinyLink/venv/lib64/python3.9/site-packages/django_extensions/management/technical_response.py", line 42, in null_technical_500_response
    raise exc_value
  File "/data/work/arysto/TinyLink/venv/lib64/python3.9/site-packages/django/core/handlers/exception.py", line 55, in inner
    response = get_response(request)
  File "/data/work/arysto/TinyLink/venv/lib64/python3.9/site-packages/django/utils/deprecation.py", line 134, in __call__
    response = response or self.get_response(request)
  File "/data/work/arysto/TinyLink/venv/lib64/python3.9/site-packages/django/core/handlers/exception.py", line 57, in inner
    response = response_for_exception(request, exc)
  File "/data/work/arysto/TinyLink/venv/lib64/python3.9/site-packages/django/core/handlers/exception.py", line 130, in response_for_exception
    response = debug.technical_500_response(
  File "/data/work/arysto/TinyLink/venv/lib64/python3.9/site-packages/django_extensions/management/technical_response.py", line 42, in null_technical_500_response
    raise exc_value
  File "/data/work/arysto/TinyLink/venv/lib64/python3.9/site-packages/django/core/handlers/exception.py", line 55, in inner
    response = get_response(request)
  File "/data/work/arysto/TinyLink/venv/lib64/python3.9/site-packages/django/utils/deprecation.py", line 133, in __call__
    response = self.process_request(request)
  File "/data/work/arysto/TinyLink/venv/lib64/python3.9/site-packages/django/middleware/common.py", line 48, in process_request
    host = request.get_host()
  File "/data/work/arysto/TinyLink/venv/lib64/python3.9/site-packages/django/http/request.py", line 150, in get_host
    raise DisallowedHost(msg)
django.core.exceptions.DisallowedHost: Invalid HTTP_HOST header: '150.254.165.23:8080'. You may need to add '150.254.165.23' to ALLOWED_HOSTS.
Invalid HTTP_HOST header: '150.254.165.23:8080'. You may need to add '150.254.165.23' to ALLOWED_HOSTS.
Traceback (most recent call last):
  File "/data/work/arysto/TinyLink/venv/lib64/python3.9/site-packages/django/core/handlers/exception.py", line 55, in inner
    response = get_response(request)
  File "/data/work/arysto/TinyLink/venv/lib64/python3.9/site-packages/corsheaders/middleware.py", line 56, in __call__
    result = self.get_response(request)
  File "/data/work/arysto/TinyLink/venv/lib64/python3.9/site-packages/django/core/handlers/exception.py", line 57, in inner
    response = response_for_exception(request, exc)
  File "/data/work/arysto/TinyLink/venv/lib64/python3.9/site-packages/django/core/handlers/exception.py", line 130, in response_for_exception
    response = debug.technical_500_response(
  File "/data/work/arysto/TinyLink/venv/lib64/python3.9/site-packages/django_extensions/management/technical_response.py", line 42, in null_technical_500_response
    raise exc_value
  File "/data/work/arysto/TinyLink/venv/lib64/python3.9/site-packages/django/core/handlers/exception.py", line 55, in inner
    response = get_response(request)
  File "/data/work/arysto/TinyLink/venv/lib64/python3.9/site-packages/django/utils/deprecation.py", line 134, in __call__
    response = response or self.get_response(request)
  File "/data/work/arysto/TinyLink/venv/lib64/python3.9/site-packages/django/core/handlers/exception.py", line 57, in inner
    response = response_for_exception(request, exc)
  File "/data/work/arysto/TinyLink/venv/lib64/python3.9/site-packages/django/core/handlers/exception.py", line 130, in response_for_exception
    response = debug.technical_500_response(
  File "/data/work/arysto/TinyLink/venv/lib64/python3.9/site-packages/django_extensions/management/technical_response.py", line 42, in null_technical_500_response
    raise exc_value
  File "/data/work/arysto/TinyLink/venv/lib64/python3.9/site-packages/django/core/handlers/exception.py", line 55, in inner
    response = get_response(request)
  File "/data/work/arysto/TinyLink/venv/lib64/python3.9/site-packages/django/utils/deprecation.py", line 134, in __call__
    response = response or self.get_response(request)
  File "/data/work/arysto/TinyLink/venv/lib64/python3.9/site-packages/django/core/handlers/exception.py", line 57, in inner
    response = response_for_exception(request, exc)
  File "/data/work/arysto/TinyLink/venv/lib64/python3.9/site-packages/django/core/handlers/exception.py", line 130, in response_for_exception
    response = debug.technical_500_response(
  File "/data/work/arysto/TinyLink/venv/lib64/python3.9/site-packages/django_extensions/management/technical_response.py", line 42, in null_technical_500_response
    raise exc_value
  File "/data/work/arysto/TinyLink/venv/lib64/python3.9/site-packages/django/core/handlers/exception.py", line 55, in inner
    response = get_response(request)
  File "/data/work/arysto/TinyLink/venv/lib64/python3.9/site-packages/django/utils/deprecation.py", line 133, in __call__
    response = self.process_request(request)
  File "/data/work/arysto/TinyLink/venv/lib64/python3.9/site-packages/django/middleware/common.py", line 48, in process_request
    host = request.get_host()
  File "/data/work/arysto/TinyLink/venv/lib64/python3.9/site-packages/django/http/request.py", line 150, in get_host
    raise DisallowedHost(msg)
django.core.exceptions.DisallowedHost: Invalid HTTP_HOST header: '150.254.165.23:8080'. You may need to add '150.254.165.23' to ALLOWED_HOSTS.
104.234.115.146 - - [22/May/2025 10:42:32] "[35m[1mGET /webpages/login.html HTTP/1.1[0m" 500 -
Traceback (most recent call last):
  File "/data/work/arysto/TinyLink/venv/lib64/python3.9/site-packages/django/contrib/staticfiles/handlers.py", line 80, in __call__
    return self.application(environ, start_response)
  File "/data/work/arysto/TinyLink/venv/lib64/python3.9/site-packages/django/core/handlers/wsgi.py", line 124, in __call__
    response = self.get_response(request)
  File "/data/work/arysto/TinyLink/venv/lib64/python3.9/site-packages/django/core/handlers/base.py", line 140, in get_response
    response = self._middleware_chain(request)
  File "/data/work/arysto/TinyLink/venv/lib64/python3.9/site-packages/django/core/handlers/exception.py", line 57, in inner
    response = response_for_exception(request, exc)
  File "/data/work/arysto/TinyLink/venv/lib64/python3.9/site-packages/django/core/handlers/exception.py", line 130, in response_for_exception
    response = debug.technical_500_response(
  File "/data/work/arysto/TinyLink/venv/lib64/python3.9/site-packages/django_extensions/management/technical_response.py", line 42, in null_technical_500_response
    raise exc_value
  File "/data/work/arysto/TinyLink/venv/lib64/python3.9/site-packages/django/core/handlers/exception.py", line 55, in inner
    response = get_response(request)
  File "/data/work/arysto/TinyLink/venv/lib64/python3.9/site-packages/corsheaders/middleware.py", line 56, in __call__
    result = self.get_response(request)
  File "/data/work/arysto/TinyLink/venv/lib64/python3.9/site-packages/django/core/handlers/exception.py", line 57, in inner
    response = response_for_exception(request, exc)
  File "/data/work/arysto/TinyLink/venv/lib64/python3.9/site-packages/django/core/handlers/exception.py", line 130, in response_for_exception
    response = debug.technical_500_response(
  File "/data/work/arysto/TinyLink/venv/lib64/python3.9/site-packages/django_extensions/management/technical_response.py", line 42, in null_technical_500_response
    raise exc_value
  File "/data/work/arysto/TinyLink/venv/lib64/python3.9/site-packages/django/core/handlers/exception.py", line 55, in inner
    response = get_response(request)
  File "/data/work/arysto/TinyLink/venv/lib64/python3.9/site-packages/django/utils/deprecation.py", line 134, in __call__
    response = response or self.get_response(request)
  File "/data/work/arysto/TinyLink/venv/lib64/python3.9/site-packages/django/core/handlers/exception.py", line 57, in inner
    response = response_for_exception(request, exc)
  File "/data/work/arysto/TinyLink/venv/lib64/python3.9/site-packages/django/core/handlers/exception.py", line 130, in response_for_exception
    response = debug.technical_500_response(
  File "/data/work/arysto/TinyLink/venv/lib64/python3.9/site-packages/django_extensions/management/technical_response.py", line 42, in null_technical_500_response
    raise exc_value
  File "/data/work/arysto/TinyLink/venv/lib64/python3.9/site-packages/django/core/handlers/exception.py", line 55, in inner
    response = get_response(request)
  File "/data/work/arysto/TinyLink/venv/lib64/python3.9/site-packages/django/utils/deprecation.py", line 134, in __call__
    response = response or self.get_response(request)
  File "/data/work/arysto/TinyLink/venv/lib64/python3.9/site-packages/django/core/handlers/exception.py", line 57, in inner
    response = response_for_exception(request, exc)
  File "/data/work/arysto/TinyLink/venv/lib64/python3.9/site-packages/django/core/handlers/exception.py", line 130, in response_for_exception
    response = debug.technical_500_response(
  File "/data/work/arysto/TinyLink/venv/lib64/python3.9/site-packages/django_extensions/management/technical_response.py", line 42, in null_technical_500_response
    raise exc_value
  File "/data/work/arysto/TinyLink/venv/lib64/python3.9/site-packages/django/core/handlers/exception.py", line 55, in inner
    response = get_response(request)
  File "/data/work/arysto/TinyLink/venv/lib64/python3.9/site-packages/django/utils/deprecation.py", line 133, in __call__
    response = self.process_request(request)
  File "/data/work/arysto/TinyLink/venv/lib64/python3.9/site-packages/django/middleware/common.py", line 48, in process_request
    host = request.get_host()
  File "/data/work/arysto/TinyLink/venv/lib64/python3.9/site-packages/django/http/request.py", line 150, in get_host
    raise DisallowedHost(msg)
django.core.exceptions.DisallowedHost: Invalid HTTP_HOST header: '150.254.165.23:8080'. You may need to add '150.254.165.23' to ALLOWED_HOSTS.
213.156.116.67 - - [22/May/2025 10:42:48] "POST /api/v1.0/get_tokens/ HTTP/1.1" 200 -
213.156.116.67 - - [22/May/2025 10:42:50] "POST /api/v1.0/refresh_token/ HTTP/1.1" 200 -
Bad Request: /api/v1.0/short/
213.156.116.67 - - [22/May/2025 10:42:51] "[31m[1mPOST /api/v1.0/short/ HTTP/1.1[0m" 400 -
213.156.116.67 - - [22/May/2025 10:42:55] "POST /api/v1.0/refresh_token/ HTTP/1.1" 200 -
213.156.116.67 - - [22/May/2025 10:42:55] "POST /api/v1.0/short/ HTTP/1.1" 200 -
213.156.116.67 - - [22/May/2025 10:43:05] "POST /api/v1.0/refresh_token/ HTTP/1.1" 200 -
213.156.116.67 - - [22/May/2025 10:43:05] "POST /api/v1.0/short/ HTTP/1.1" 200 -
213.156.116.67 - - [22/May/2025 10:43:09] "POST /api/v1.0/get_tokens/ HTTP/1.1" 200 -
213.156.116.67 - - [22/May/2025 10:43:13] "POST /api/v1.0/refresh_token/ HTTP/1.1" 200 -
213.156.116.67 - - [22/May/2025 10:43:13] "POST /api/v1.0/short/ HTTP/1.1" 200 -
213.156.116.67 - - [22/May/2025 10:44:38] "POST /api/v1.0/get_tokens/ HTTP/1.1" 200 -
213.156.116.67 - - [22/May/2025 10:44:40] "POST /api/v1.0/refresh_token/ HTTP/1.1" 200 -
Bad Request: /api/v1.0/short/
213.156.116.67 - - [22/May/2025 10:44:40] "[31m[1mPOST /api/v1.0/short/ HTTP/1.1[0m" 400 -
213.156.116.67 - - [22/May/2025 10:44:49] "POST /api/v1.0/refresh_token/ HTTP/1.1" 200 -
213.156.116.67 - - [22/May/2025 10:44:49] "POST /api/v1.0/short/ HTTP/1.1" 200 -
213.156.116.67 - - [22/May/2025 10:52:08] "OPTIONS /api/v1.0/get_tokens/ HTTP/1.1" 200 -
213.156.116.67 - - [22/May/2025 10:52:09] "POST /api/v1.0/get_tokens/ HTTP/1.1" 200 -
213.156.116.67 - - [22/May/2025 10:52:10] "OPTIONS /api/v1.0/refresh_token/ HTTP/1.1" 200 -
213.156.116.67 - - [22/May/2025 10:52:10] "POST /api/v1.0/refresh_token/ HTTP/1.1" 200 -
213.156.116.67 - - [22/May/2025 10:52:10] "OPTIONS /api/v1.0/short/ HTTP/1.1" 200 -
Bad Request: /api/v1.0/short/
213.156.116.67 - - [22/May/2025 10:52:11] "[31m[1mPOST /api/v1.0/short/ HTTP/1.1[0m" 400 -
213.156.116.67 - - [22/May/2025 10:52:12] "POST /api/v1.0/refresh_token/ HTTP/1.1" 200 -
Bad Request: /api/v1.0/short/
213.156.116.67 - - [22/May/2025 10:52:12] "[31m[1mPOST /api/v1.0/short/ HTTP/1.1[0m" 400 -
213.156.116.67 - - [22/May/2025 10:52:12] "POST /api/v1.0/refresh_token/ HTTP/1.1" 200 -
Bad Request: /api/v1.0/short/
213.156.116.67 - - [22/May/2025 10:52:12] "[31m[1mPOST /api/v1.0/short/ HTTP/1.1[0m" 400 -
213.156.116.67 - - [22/May/2025 10:52:13] "POST /api/v1.0/refresh_token/ HTTP/1.1" 200 -
Bad Request: /api/v1.0/short/
213.156.116.67 - - [22/May/2025 10:52:13] "[31m[1mPOST /api/v1.0/short/ HTTP/1.1[0m" 400 -
213.156.116.67 - - [22/May/2025 10:52:13] "POST /api/v1.0/refresh_token/ HTTP/1.1" 200 -
Bad Request: /api/v1.0/short/
213.156.116.67 - - [22/May/2025 10:52:13] "[31m[1mPOST /api/v1.0/short/ HTTP/1.1[0m" 400 -
213.156.116.67 - - [22/May/2025 10:52:14] "POST /api/v1.0/refresh_token/ HTTP/1.1" 200 -
Too Many Requests: /api/v1.0/short/
213.156.116.67 - - [22/May/2025 10:52:14] "[31m[1mPOST /api/v1.0/short/ HTTP/1.1[0m" 429 -
77.65.103.19 - - [22/May/2025 10:57:48] "OPTIONS /api/v1.0/get_tokens/ HTTP/1.1" 200 -
77.65.103.19 - - [22/May/2025 10:57:49] "POST /api/v1.0/get_tokens/ HTTP/1.1" 200 -
77.65.103.19 - - [22/May/2025 10:57:50] "OPTIONS /api/v1.0/refresh_token/ HTTP/1.1" 200 -
77.65.103.19 - - [22/May/2025 10:57:50] "POST /api/v1.0/refresh_token/ HTTP/1.1" 200 -
77.65.103.19 - - [22/May/2025 10:57:50] "OPTIONS /api/v1.0/short/ HTTP/1.1" 200 -
Bad Request: /api/v1.0/short/
77.65.103.19 - - [22/May/2025 10:57:50] "[31m[1mPOST /api/v1.0/short/ HTTP/1.1[0m" 400 -
213.156.116.67 - - [22/May/2025 11:18:48] "POST /api/v1.0/refresh_token/ HTTP/1.1" 200 -
213.156.116.67 - - [22/May/2025 11:18:48] "POST /api/v1.0/short/ HTTP/1.1" 200 -
213.156.116.67 - - [22/May/2025 11:18:50] "POST /api/v1.0/refresh_token/ HTTP/1.1" 200 -
213.156.116.67 - - [22/May/2025 11:18:50] "POST /api/v1.0/short/ HTTP/1.1" 200 -
213.156.116.67 - - [22/May/2025 11:48:46] "POST /api/v1.0/refresh_token/ HTTP/1.1" 200 -
Bad Request: /api/v1.0/short/
213.156.116.67 - - [22/May/2025 11:48:46] "[31m[1mPOST /api/v1.0/short/ HTTP/1.1[0m" 400 -
213.156.116.67 - - [22/May/2025 12:23:05] "OPTIONS /api/v1.0/refresh_token/ HTTP/1.1" 200 -
213.156.116.67 - - [22/May/2025 12:23:05] "POST /api/v1.0/refresh_token/ HTTP/1.1" 200 -
213.156.116.67 - - [22/May/2025 12:23:05] "OPTIONS /api/v1.0/short/ HTTP/1.1" 200 -
213.156.116.67 - - [22/May/2025 12:23:05] "POST /api/v1.0/short/ HTTP/1.1" 200 -
150.254.169.100 - - [22/May/2025 13:41:26] "GET /api/v1.0/is_alive HTTP/1.1" 200 -
150.254.169.100 - - [22/May/2025 13:41:46] "GET /api/v1.0/is_alive HTTP/1.1" 200 -
213.156.116.67 - - [22/May/2025 14:08:18] "POST /api/v1.0/refresh_token/ HTTP/1.1" 200 -
Bad Request: /api/v1.0/short/
213.156.116.67 - - [22/May/2025 14:08:18] "[31m[1mPOST /api/v1.0/short/ HTTP/1.1[0m" 400 -
213.156.116.67 - - [22/May/2025 14:12:14] "OPTIONS /api/v1.0/short/ HTTP/1.1" 200 -
Unauthorized: /api/v1.0/short/
213.156.116.67 - - [22/May/2025 14:12:14] "[31m[1mPOST /api/v1.0/short/ HTTP/1.1[0m" 401 -
Unauthorized: /api/v1.0/short/
213.156.116.67 - - [22/May/2025 14:12:21] "[31m[1mPOST /api/v1.0/short/ HTTP/1.1[0m" 401 -
213.156.116.67 - - [22/May/2025 14:12:30] "OPTIONS /api/v1.0/get_tokens/ HTTP/1.1" 200 -
213.156.116.67 - - [22/May/2025 14:12:31] "POST /api/v1.0/get_tokens/ HTTP/1.1" 200 -
213.156.116.67 - - [22/May/2025 14:12:31] "OPTIONS /api/v1.0/refresh_token/ HTTP/1.1" 200 -
213.156.116.67 - - [22/May/2025 14:12:31] "POST /api/v1.0/refresh_token/ HTTP/1.1" 200 -
213.156.116.67 - - [22/May/2025 14:12:31] "OPTIONS /api/v1.0/short/ HTTP/1.1" 200 -
Bad Request: /api/v1.0/short/
213.156.116.67 - - [22/May/2025 14:12:31] "[31m[1mPOST /api/v1.0/short/ HTTP/1.1[0m" 400 -
